{"code": 11001, "msg": "登录失败，用户名或密码错误", "@timestamp": "2020-11-19 08:21:17.654424", "error": "libs.exceptions.LoginFailed", "errormsg": "登录失败，用户名或密码错误", "errorpath": ["File \"D:\\GitHub\\DRF-iView\\rbac\\views.py\", line 84, in post"], "method": "POST", "url": "/rbac/login/", "user": null, "params": {}, "data": {"username": "kinson.liu", "password": "lqs4568349"}}
{"code": 11001, "msg": "登录失败，用户名或密码错误", "@timestamp": "2020-11-19 08:21:30.502165", "error": "libs.exceptions.LoginFailed", "errormsg": "登录失败，用户名或密码错误", "errorpath": ["File \"D:\\GitHub\\DRF-iView\\rbac\\views.py\", line 84, in post"], "method": "POST", "url": "/rbac/login/", "user": null, "params": {}, "data": {"username": "admin", "password": "admin"}}
{"code": 11001, "msg": "登录失败，用户名或密码错误", "@timestamp": "2020-11-19 08:21:34.627107", "error": "libs.exceptions.LoginFailed", "errormsg": "登录失败，用户名或密码错误", "errorpath": ["File \"D:\\GitHub\\DRF-iView\\rbac\\views.py\", line 84, in post"], "method": "POST", "url": "/rbac/login/", "user": null, "params": {}, "data": {"username": "admin", "password": "admin"}}
{"code": 10000, "msg": "服务器内部错误", "@timestamp": "2020-11-19 08:35:49.912295", "error": "redis.exceptions.ConnectionError", "errormsg": "Error 10060 connecting to 10.30.10.120:6379. 由于连接方在一段时间后没有正确答复或连接的主机没有反应，连接尝试失败。.", "errorpath": ["File \"D:\\GitHub\\DRF-iView\\rbac\\views.py\", line 80, in post", "File \"D:\\GitHub\\DRF-iView\\libs\\authtication.py\", line 43, in create_token"], "method": "POST", "url": "/rbac/login/", "user": null, "params": {}, "data": {"username": "admin", "password": "admin"}}
{"code": 10000, "msg": "服务器内部错误", "@timestamp": "2020-11-19 08:36:44.159480", "error": "redis.exceptions.ConnectionError", "errormsg": "Error 10060 connecting to 10.30.10.120:6379. 由于连接方在一段时间后没有正确答复或连接的主机没有反应，连接尝试失败。.", "errorpath": ["File \"D:\\GitHub\\DRF-iView\\rbac\\views.py\", line 80, in post", "File \"D:\\GitHub\\DRF-iView\\libs\\authtication.py\", line 43, in create_token"], "method": "POST", "url": "/rbac/login/", "user": null, "params": {}, "data": {"username": "admin", "password": "admin"}}
{"code": 11001, "msg": "登录失败，用户名或密码错误", "@timestamp": "2020-11-19 08:38:24.953637", "error": "libs.exceptions.LoginFailed", "errormsg": "登录失败，用户名或密码错误", "errorpath": ["File \"D:\\GitHub\\DRF-iView\\rbac\\views.py\", line 84, in post"], "method": "POST", "url": "/rbac/login/", "user": null, "params": {}, "data": {"username": "admin", "password": "admin"}}
{"code": 10000, "msg": "服务器内部错误", "@timestamp": "2020-11-19 08:45:11.979468", "error": "redis.exceptions.ConnectionError", "errormsg": "Error 10060 connecting to 10.30.10.120:6379. 由于连接方在一段时间后没有正确答复或连接的主机没有反应，连接尝试失败。.", "errorpath": ["File \"D:\\GitHub\\DRF-iView\\rbac\\views.py\", line 80, in post", "File \"D:\\GitHub\\DRF-iView\\libs\\authtication.py\", line 43, in create_token"], "method": "POST", "url": "/rbac/login/", "user": null, "params": {}, "data": {"username": "admin", "password": "admin"}}
{"code": 10000, "msg": "服务器内部错误", "@timestamp": "2020-11-19 08:45:32.984349", "error": "redis.exceptions.ConnectionError", "errormsg": "Error 10060 connecting to 10.30.10.120:6379. 由于连接方在一段时间后没有正确答复或连接的主机没有反应，连接尝试失败。.", "errorpath": ["File \"D:\\GitHub\\DRF-iView\\rbac\\views.py\", line 80, in post", "File \"D:\\GitHub\\DRF-iView\\libs\\authtication.py\", line 43, in create_token"], "method": "POST", "url": "/rbac/login/", "user": null, "params": {}, "data": {"username": "admin", "password": "admin"}}
{"code": 10001, "msg": "Token认证失败", "@timestamp": "2020-11-19 11:50:43.887813", "error": "libs.exceptions.AuthenticationFailed", "errormsg": "Token认证失败", "errorpath": ["File \"D:\\Django\\Program\\ztx\\server\\libs\\authtication.py\", line 25, in authenticate"], "method": "GET", "url": "/ztx/", "user": null, "params": {}, "data": {}}
{"code": 10001, "msg": "Token认证失败", "@timestamp": "2020-11-19 11:50:57.751003", "error": "libs.exceptions.AuthenticationFailed", "errormsg": "Token认证失败", "errorpath": ["File \"D:\\Django\\Program\\ztx\\server\\libs\\authtication.py\", line 25, in authenticate"], "method": "GET", "url": "/ztx/costomer/", "user": null, "params": {}, "data": {}}
{"code": 10000, "msg": "服务器内部错误", "@timestamp": "2020-11-19 11:51:20.955126", "error": "django.db.utils.OperationalError", "errormsg": "no such table: ztx_costomer", "errorpath": [], "method": "GET", "url": "/ztx/costomer/", "user": null, "params": {}, "data": {}}
{"code": 10000, "msg": "服务器内部错误", "@timestamp": "2020-11-19 11:53:29.136644", "error": "rest_framework.exceptions.ValidationError", "errormsg": "{'money': [ErrorDetail(string='请确保小数点前不超过 4 个数字。', code='max_whole_digits')]}", "errorpath": [], "method": "POST", "url": "/ztx/costomer/", "user": null, "params": {}, "data": {"csrfmiddlewaretoken": "ACIA48uNuEB6Pwce7PgLPNcEKobKXO1rpNp47YJldn9K1HtT3ZejfZAzxU5sKpel", "create_time": "", "name": "刘青松", "phone": "17600664848", "introducer": "姜长红", "money": "10000"}}
{"code": 10000, "msg": "服务器内部错误", "@timestamp": "2020-11-19 12:02:39.437445", "error": "django.core.exceptions.FieldError", "errormsg": "Cannot resolve keyword 'introduce' into field. Choices are: create_time, id, income, introducer, is_deleted, money, name, phone, trade, update_time", "errorpath": [], "method": "GET", "url": "/ztx/costomer/", "user": null, "params": {"search": "刘"}, "data": {}}
{"code": 10000, "msg": "服务器内部错误", "@timestamp": "2020-11-19 12:03:26.082327", "error": "django.core.exceptions.FieldError", "errormsg": "Cannot resolve keyword 'introduce' into field. Choices are: create_time, id, income, introducer, is_deleted, money, name, phone, trade, update_time", "errorpath": [], "method": "GET", "url": "/ztx/costomer/", "user": null, "params": {"search": "bpm"}, "data": {}}
{"code": 10000, "msg": "服务器内部错误", "@timestamp": "2020-11-19 12:03:59.269657", "error": "django.core.exceptions.FieldError", "errormsg": "Cannot resolve keyword 'introduce' into field. Choices are: create_time, id, income, introducer, is_deleted, money, name, phone, trade, update_time", "errorpath": [], "method": "GET", "url": "/ztx/costomer/", "user": null, "params": {"search": "bpm"}, "data": {}}
{"code": 10000, "msg": "服务器内部错误", "@timestamp": "2020-11-19 12:04:11.041203", "error": "django.core.exceptions.FieldError", "errormsg": "Cannot resolve keyword 'introduce' into field. Choices are: create_time, id, income, introducer, is_deleted, money, name, phone, trade, update_time", "errorpath": [], "method": "GET", "url": "/ztx/costomer/", "user": null, "params": {"search": "123"}, "data": {}}
{"code": 10000, "msg": "服务器内部错误", "@timestamp": "2020-11-19 12:12:02.980343", "error": "TypeError", "errormsg": "'Meta.fields' contains fields that are not defined on this FilterSet: n, a, m, e", "errorpath": [], "method": "GET", "url": "/ztx/costomer/", "user": null, "params": {}, "data": {}}
{"code": 10000, "msg": "服务器内部错误", "@timestamp": "2020-11-19 12:12:07.963031", "error": "TypeError", "errormsg": "'Meta.fields' contains fields that are not defined on this FilterSet: n, a, m, e", "errorpath": [], "method": "GET", "url": "/ztx/costomer/", "user": null, "params": {}, "data": {}}
{"code": 10000, "msg": "服务器内部错误", "@timestamp": "2020-11-19 12:27:51.259937", "error": "rest_framework.exceptions.ValidationError", "errormsg": "{'create_time': [ErrorDetail(string='该字段不能为 null。', code='null')]}", "errorpath": [], "method": "POST", "url": "/ztx/income/", "user": null, "params": {}, "data": {"create_time": null, "is_deleted": false, "type": "理疗卡", "costomer_id": 1}}
{"code": 10000, "msg": "服务器内部错误", "@timestamp": "2020-11-19 12:38:59.185103", "error": "AttributeError", "errormsg": "Got AttributeError when attempting to get a value for field `costomer_name` on serializer `IncomeSerializer`.\nThe serializer field might be named incorrectly and not match any attribute or key on the `Income` instance.\nOriginal exception text was: 'Income' object has no attribute 'get_costomer_display'.", "errorpath": [], "method": "GET", "url": "/ztx/income/", "user": null, "params": {}, "data": {}}
{"code": 10000, "msg": "服务器内部错误", "@timestamp": "2020-11-19 12:44:46.776412", "error": "django.core.exceptions.ImproperlyConfigured", "errormsg": "Field name `costomer.name` is not valid for model `Income`.", "errorpath": [], "method": "GET", "url": "/ztx/income/", "user": null, "params": {}, "data": {}}
{"code": 10000, "msg": "服务器内部错误", "@timestamp": "2020-11-19 12:47:26.840072", "error": "AttributeError", "errormsg": "'IncomeSerializer' object has no attribute 'get_costomer_name'", "errorpath": [], "method": "GET", "url": "/ztx/income/", "user": null, "params": {}, "data": {}}
{"code": 10000, "msg": "服务器内部错误", "@timestamp": "2020-11-19 12:59:46.277075", "error": "AssertionError", "errormsg": "The field 'costomer_name' was declared on serializer IncomeSerializer, but has not been included in the 'fields' option.", "errorpath": [], "method": "GET", "url": "/ztx/income/", "user": null, "params": {}, "data": {}}
{"code": 10000, "msg": "服务器内部错误", "@timestamp": "2020-11-19 13:02:05.812251", "error": "django.core.exceptions.FieldError", "errormsg": "Cannot resolve keyword 'name' into field. Choices are: costomer_id, costomer_id_id, create_time, id, is_deleted, type, update_time", "errorpath": [], "method": "GET", "url": "/ztx/income/", "user": null, "params": {"search": "刘青松"}, "data": {}}
{"code": 10000, "msg": "服务器内部错误", "@timestamp": "2020-11-19 13:57:05.187559", "error": "rest_framework.exceptions.ValidationError", "errormsg": "{'create_time': [ErrorDetail(string='该字段不能为 null。', code='null')]}", "errorpath": [], "method": "POST", "url": "/ztx/trade/", "user": null, "params": {}, "data": {"create_time": null, "is_deleted": false}}
{"code": 10000, "msg": "服务器内部错误", "@timestamp": "2020-11-19 14:03:57.527278", "error": "rest_framework.exceptions.ValidationError", "errormsg": "{'create_time': [ErrorDetail(string='该字段不能为 null。', code='null')]}", "errorpath": [], "method": "POST", "url": "/ztx/trade/", "user": null, "params": {}, "data": {"create_time": null, "is_deleted": false, "product_id": 1, "costomer_id": 1}}
{"code": 10000, "msg": "服务器内部错误", "@timestamp": "2020-11-19 14:16:18.473640", "error": "AttributeError", "errormsg": "'IncomeSerializer' object has no attribute 'get_costomer_name'", "errorpath": [], "method": "GET", "url": "/ztx/income/", "user": null, "params": {}, "data": {}}
{"code": 10000, "msg": "服务器内部错误", "@timestamp": "2020-11-19 14:16:34.899751", "error": "AttributeError", "errormsg": "'Income' object has no attribute 'costomer'", "errorpath": ["File \"D:\\Django\\Program\\ztx\\server\\ztx\\serializers.py\", line 34, in get_costomer_name"], "method": "GET", "url": "/ztx/income/", "user": null, "params": {}, "data": {}}
{"code": 10000, "msg": "服务器内部错误", "@timestamp": "2020-11-19 14:17:05.279580", "error": "AttributeError", "errormsg": "'Costomer' object has no attribute 'first'", "errorpath": ["File \"D:\\Django\\Program\\ztx\\server\\ztx\\serializers.py\", line 34, in get_costomer_name"], "method": "GET", "url": "/ztx/income/", "user": null, "params": {}, "data": {}}
{"code": 10000, "msg": "服务器内部错误", "@timestamp": "2020-11-19 14:17:15.106326", "error": "AttributeError", "errormsg": "'Costomer' object has no attribute 'all'", "errorpath": ["File \"D:\\Django\\Program\\ztx\\server\\ztx\\serializers.py\", line 34, in get_costomer_name"], "method": "GET", "url": "/ztx/income/", "user": null, "params": {}, "data": {}}
{"code": 10000, "msg": "服务器内部错误", "@timestamp": "2020-11-19 14:19:26.956503", "error": "AttributeError", "errormsg": "'Costomer' object has no attribute 'all'", "errorpath": ["File \"D:\\Django\\Program\\ztx\\server\\ztx\\serializers.py\", line 35, in get_costomer_name"], "method": "GET", "url": "/ztx/income/", "user": null, "params": {}, "data": {}}
{"code": 10000, "msg": "服务器内部错误", "@timestamp": "2020-11-19 14:20:00.503962", "error": "AttributeError", "errormsg": "'Costomer' object has no attribute 'all'", "errorpath": ["File \"D:\\Django\\Program\\ztx\\server\\ztx\\serializers.py\", line 35, in get_costomer_name"], "method": "GET", "url": "/ztx/income/", "user": null, "params": {}, "data": {}}
{"code": 10000, "msg": "服务器内部错误", "@timestamp": "2020-11-19 14:26:43.469396", "error": "AttributeError", "errormsg": "'Income' object has no attribute 'all'", "errorpath": ["File \"D:\\Django\\Program\\ztx\\server\\ztx\\serializers.py\", line 34, in get_costomer_name"], "method": "GET", "url": "/ztx/income/", "user": null, "params": {}, "data": {}}
{"code": 10000, "msg": "服务器内部错误", "@timestamp": "2020-11-19 14:27:44.665859", "error": "AttributeError", "errormsg": "'Costomer' object has no attribute 'all'", "errorpath": ["File \"D:\\Django\\Program\\ztx\\server\\ztx\\serializers.py\", line 34, in get_costomer_name"], "method": "GET", "url": "/ztx/income/", "user": null, "params": {}, "data": {}}
{"code": 10000, "msg": "服务器内部错误", "@timestamp": "2020-11-19 14:27:46.395270", "error": "AttributeError", "errormsg": "'Costomer' object has no attribute 'all'", "errorpath": ["File \"D:\\Django\\Program\\ztx\\server\\ztx\\serializers.py\", line 34, in get_costomer_name"], "method": "GET", "url": "/ztx/income/", "user": null, "params": {}, "data": {}}
{"code": 10000, "msg": "服务器内部错误", "@timestamp": "2020-11-19 14:29:05.881170", "error": "AttributeError", "errormsg": "'Income' object has no attribute 'object'", "errorpath": ["File \"D:\\Django\\Program\\ztx\\server\\ztx\\serializers.py\", line 34, in get_costomer_name"], "method": "GET", "url": "/ztx/income/", "user": null, "params": {}, "data": {}}
{"code": 10000, "msg": "服务器内部错误", "@timestamp": "2020-11-19 14:29:26.510077", "error": "AttributeError", "errormsg": "'Income' object has no attribute 'object'", "errorpath": ["File \"D:\\Django\\Program\\ztx\\server\\ztx\\serializers.py\", line 34, in get_costomer_name"], "method": "GET", "url": "/ztx/income/", "user": null, "params": {}, "data": {}}
{"code": 10000, "msg": "服务器内部错误", "@timestamp": "2020-11-19 14:30:19.126468", "error": "AttributeError", "errormsg": "'Income' object has no attribute 'costomer'", "errorpath": ["File \"D:\\Django\\Program\\ztx\\server\\ztx\\serializers.py\", line 34, in get_costomer_name"], "method": "GET", "url": "/ztx/income/", "user": null, "params": {}, "data": {}}
{"code": 10000, "msg": "服务器内部错误", "@timestamp": "2020-11-19 14:30:20.464893", "error": "AttributeError", "errormsg": "'Income' object has no attribute 'costomer'", "errorpath": ["File \"D:\\Django\\Program\\ztx\\server\\ztx\\serializers.py\", line 34, in get_costomer_name"], "method": "GET", "url": "/ztx/income/", "user": null, "params": {}, "data": {}}
{"code": 10000, "msg": "服务器内部错误", "@timestamp": "2020-11-19 14:41:46.412776", "error": "AttributeError", "errormsg": "Got AttributeError when attempting to get a value for field `costomer_name` on serializer `IncomeSerializer`.\nThe serializer field might be named incorrectly and not match any attribute or key on the `Income` instance.\nOriginal exception text was: 'Income' object has no attribute 'Costomer'.", "errorpath": [], "method": "GET", "url": "/ztx/income/", "user": null, "params": {}, "data": {}}
{"code": 10000, "msg": "服务器内部错误", "@timestamp": "2020-11-19 14:44:53.201650", "error": "django.core.exceptions.FieldError", "errormsg": "Cannot resolve keyword 'costomer_name' into field. Choices are: costomer, costomer_id, create_time, id, is_deleted, type, update_time", "errorpath": [], "method": "GET", "url": "/ztx/income/", "user": null, "params": {"search": "1"}, "data": {}}
{"code": 10000, "msg": "服务器内部错误", "@timestamp": "2020-11-19 14:52:11.792924", "error": "AttributeError", "errormsg": "Got AttributeError when attempting to get a value for field `costomer_name` on serializer `TradeSerializer`.\nThe serializer field might be named incorrectly and not match any attribute or key on the `Trade` instance.\nOriginal exception text was: 'NoneType' object has no attribute 'name'.", "errorpath": [], "method": "GET", "url": "/ztx/trade/", "user": null, "params": {}, "data": {}}
{"code": 10000, "msg": "服务器内部错误", "@timestamp": "2020-11-19 14:52:52.401402", "error": "AttributeError", "errormsg": "Got AttributeError when attempting to get a value for field `product_name` on serializer `TradeSerializer`.\nThe serializer field might be named incorrectly and not match any attribute or key on the `Trade` instance.\nOriginal exception text was: 'NoneType' object has no attribute 'name'.", "errorpath": [], "method": "GET", "url": "/ztx/trade/", "user": null, "params": {}, "data": {}}
{"code": 10000, "msg": "服务器内部错误", "@timestamp": "2020-11-19 14:53:21.746027", "error": "AttributeError", "errormsg": "Got AttributeError when attempting to get a value for field `product_name` on serializer `TradeSerializer`.\nThe serializer field might be named incorrectly and not match any attribute or key on the `Trade` instance.\nOriginal exception text was: 'NoneType' object has no attribute 'name'.", "errorpath": [], "method": "GET", "url": "/ztx/trade/", "user": null, "params": {}, "data": {}}
{"code": 10000, "msg": "服务器内部错误", "@timestamp": "2020-11-19 14:53:44.576995", "error": "AssertionError", "errormsg": "The field 'product_name' was declared on serializer TradeSerializer, but has not been included in the 'fields' option.", "errorpath": [], "method": "GET", "url": "/ztx/trade/", "user": null, "params": {}, "data": {}}
